<?xml version="1.0"?>
<robot xmlns:xacro="http://www.ros.org/wiki/xacro">

  <!-- Taken from https://github.com/ros-controls/ros_controllers/blob/noetic-devel/diff_drive_controller/test/wheel.xacro -->

  <xacro:macro name="wheel" params="name parent radius thickness *origin">
    <link name="${name}_link">
      <inertial>
        <origin xyz="0 0 0" rpy="0 0 0"/>
        <mass value="1"/>
        <inertia ixx="0.2" ixy="0" ixz="0" iyy="0.2" iyz="0" izz="0.2"/>
      </inertial>
      <visual>
        <origin xyz="0 0 0" rpy="0 0 0"/>
        <geometry>
          <cylinder radius="${radius}" length="${thickness}"/>
        </geometry>
        <material name="black">
          <color rgba="0 0 0 1"/>
        </material>
      </visual>
      <collision>
        <origin xyz="0 0 0" rpy="0 0 0"/>
        <geometry>
          <cylinder radius="${radius}" length="${thickness}"/>
        </geometry>
      </collision>
    </link>

    <joint name="${name}_joint" type="continuous">
      <parent link="${parent}"/>
      <child link="${name}_link"/>
      <xacro:insert_block name="origin"/>
      <axis xyz="0 0 1"/>
    </joint>
  </xacro:macro>

</robot>
